v9: 8f6d86a Merge pull request #5465 from emcastillo/bdocs-vb9
Traceback (most recent call last):
  File "/home/kmaeh/.pyenv/versions/3.8.7/lib/python3.8/runpy.py", line 194, in _run_module_as_main
    return _run_code(code, main_globals, None,
  File "/home/kmaeh/.pyenv/versions/3.8.7/lib/python3.8/runpy.py", line 87, in _run_code
    exec(code, run_globals)
  File "/home/kmaeh/.pyenv/versions/rocm-ci/lib/python3.8/site-packages/pytest/__main__.py", line 5, in <module>
    raise SystemExit(pytest.console_main())
  File "/home/kmaeh/.pyenv/versions/rocm-ci/lib/python3.8/site-packages/_pytest/config/__init__.py", line 185, in console_main
    code = main()
  File "/home/kmaeh/.pyenv/versions/rocm-ci/lib/python3.8/site-packages/_pytest/config/__init__.py", line 162, in main
    ret: Union[ExitCode, int] = config.hook.pytest_cmdline_main(
  File "/home/kmaeh/.pyenv/versions/rocm-ci/lib/python3.8/site-packages/pluggy/hooks.py", line 286, in __call__
    return self._hookexec(self, self.get_hookimpls(), kwargs)
  File "/home/kmaeh/.pyenv/versions/rocm-ci/lib/python3.8/site-packages/pluggy/manager.py", line 93, in _hookexec
    return self._inner_hookexec(hook, methods, kwargs)
  File "/home/kmaeh/.pyenv/versions/rocm-ci/lib/python3.8/site-packages/pluggy/manager.py", line 84, in <lambda>
    self._inner_hookexec = lambda hook, methods, kwargs: hook.multicall(
  File "/home/kmaeh/.pyenv/versions/rocm-ci/lib/python3.8/site-packages/pluggy/callers.py", line 208, in _multicall
    return outcome.get_result()
  File "/home/kmaeh/.pyenv/versions/rocm-ci/lib/python3.8/site-packages/pluggy/callers.py", line 80, in get_result
    raise ex[1].with_traceback(ex[2])
  File "/home/kmaeh/.pyenv/versions/rocm-ci/lib/python3.8/site-packages/pluggy/callers.py", line 187, in _multicall
    res = hook_impl.function(*args)
  File "/home/kmaeh/.pyenv/versions/rocm-ci/lib/python3.8/site-packages/_pytest/main.py", line 316, in pytest_cmdline_main
    return wrap_session(config, _main)
  File "/home/kmaeh/.pyenv/versions/rocm-ci/lib/python3.8/site-packages/_pytest/main.py", line 304, in wrap_session
    config.hook.pytest_sessionfinish(
  File "/home/kmaeh/.pyenv/versions/rocm-ci/lib/python3.8/site-packages/pluggy/hooks.py", line 286, in __call__
    return self._hookexec(self, self.get_hookimpls(), kwargs)
  File "/home/kmaeh/.pyenv/versions/rocm-ci/lib/python3.8/site-packages/pluggy/manager.py", line 93, in _hookexec
    return self._inner_hookexec(hook, methods, kwargs)
  File "/home/kmaeh/.pyenv/versions/rocm-ci/lib/python3.8/site-packages/pluggy/manager.py", line 84, in <lambda>
    self._inner_hookexec = lambda hook, methods, kwargs: hook.multicall(
  File "/home/kmaeh/.pyenv/versions/rocm-ci/lib/python3.8/site-packages/pluggy/callers.py", line 203, in _multicall
    gen.send(outcome)
  File "/home/kmaeh/.pyenv/versions/rocm-ci/lib/python3.8/site-packages/_pytest/terminal.py", line 803, in pytest_sessionfinish
    outcome.get_result()
  File "/home/kmaeh/.pyenv/versions/rocm-ci/lib/python3.8/site-packages/pluggy/callers.py", line 80, in get_result
    raise ex[1].with_traceback(ex[2])
  File "/home/kmaeh/.pyenv/versions/rocm-ci/lib/python3.8/site-packages/pluggy/callers.py", line 187, in _multicall
    res = hook_impl.function(*args)
  File "/home/kmaeh/.pyenv/versions/rocm-ci/lib/python3.8/site-packages/pytest_html/plugin.py", line 758, in pytest_sessionfinish
    self._save_report(report_content)
  File "/home/kmaeh/.pyenv/versions/rocm-ci/lib/python3.8/site-packages/pytest_html/plugin.py", line 683, in _save_report
    f.write(report_content)
OSError: [Errno 28] No space left on device
============================= test session starts ==============================
platform linux -- Python 3.8.7, pytest-6.2.2, py-1.10.0, pluggy-0.13.1
rootdir: /home/kmaeh/Development/cupy-rocm-ci-report/tools/tmp.99tI5ririF/cupy, configfile: setup.cfg
plugins: html-3.1.1, metadata-1.11.0
collected 0 items / 206 errors
!!!!!!!!!!!!!!!!!! Interrupted: 206 errors during collection !!!!!!!!!!!!!!!!!!!
